Workbook

Sheet Movies
A1: id | B1: title | C1: genre_ids | D1: release_date | E1: original_language | F1: popularity | G1: vote_average | H1: vote_count | I1: genres | J1: content_type | K1: content_type2
A2: 1169516 | B2: Welcome to the Jungle | C2: [28, 35, 12, 80] | D2: 2026 | E2: hi | F2: 597.0277 | G2: 5.3 | H2: 12 | I2: Action | J2: Movie | K2: Movie
A3: 1169516 | B3: Welcome to the Jungle | C3: [28, 35, 12, 80] | D3: 2026 | E3: hi | F3: 597.0277 | G3: 5.3 | H3: 12 | I3: Comedy | J3: Movie | K3: Movie
A4: 1169516 | B4: Welcome to the Jungle | C4: [28, 35, 12, 80] | D4: 2026 | E4: hi | F4: 597.0277 | G4: 5.3 | H4: 12 | I4: Adventure | J4: Movie | K4: Movie
A5: 1169516 | B5: Welcome to the Jungle | C5: [28, 35, 12, 80] | D5: 2026 | E5: hi | F5: 597.0277 | G5: 5.3 | H5: 12 | I5: Crime | J5: Movie | K5: Movie
A6: 1275779 | B6: Disclosure Day | C6: [878, 53] | D6: 2026 | E6: en | F6: 592.339 | G6: 6.69 | H6: 730 | I6: Science Fiction | J6: Movie | K6: Movie
A7: 1275779 | B7: Disclosure Day | C7: [878, 53] | D7: 2026 | E7: en | F7: 592.339 | G7: 6.69 | H7: 730 | I7: Thriller | J7: Movie | K7: Movie
A8: 1084244 | B8: Toy Story 5 | C8: [16, 10751, 35, 12] | D8: 2026 | E8: en | F8: 555.254 | G8: 7.473 | H8: 374 | I8: Animation | J8: Movie | K8: Movie
A9: 1084244 | B9: Toy Story 5 | C9: [16, 10751, 35, 12] | D9: 2026 | E9: en | F9: 555.254 | G9: 7.473 | H9: 374 | I9: Family | J9: Movie | K9: Movie
A10: 1084244 | B10: Toy Story 5 | C10: [16, 10751, 35, 12] | D10: 2026 | E10: en | F10: 555.254 | G10: 7.473 | H10: 374 | I10: Comedy | J10: Movie | K10: Movie
A11: 1084244 | B11: Toy Story 5 | C11: [16, 10751, 35, 12] | D11: 2026 | E11: en | F11: 555.254 | G11: 7.473 | H11: 374 | I11: Adventure | J11: Movie | K11: Movie
A12: 1083381 | B12: Backrooms | C12: [27, 9648, 878] | D12: 2026 | E12: en | F12: 457.4145 | G12: 6.85 | H12: 791 | I12: Horror | J12: Movie | K12: Movie
A13: 1083381 | B13: Backrooms | C13: [27, 9648, 878] | D13: 2026 | E13: en | F13: 457.4145 | G13: 6.85 | H13: 791 | I13: Mystery | J13: Movie | K13: Movie
... A459: 372058 | B459: Your Name. | C459: [16, 10749, 18] | D459: 2016 | E459: ja | F459: 30.533 | G459: 8.481 | H459: 12652 | I459: Drama | J459: Movie | K459: Movie
A460: 1137129 | B460: Pedro Had a Horse | C460: [] | D460: 2023 | E460: pt | F460: 30.4934 | G460: 8.5 | H460: 2 | J460: Movie | K460: Movie
A461: 1168190 | B461: The Wrecking Crew | C461: [28, 35, 80, 9648] | D461: 2026 | E461: en | F461: 30.4309 | G461: 7.037 | H461: 1102 | I461: Action | J461: Movie | K461: Movie
A462: 1168190 | B462: The Wrecking Crew | C462: [28, 35, 80, 9648] | D462: 2026 | E462: en | F462: 30.4309 | G462: 7.037 | H462: 1102 | I462: Comedy | J462: Movie | K462: Movie
A463: 1168190 | B463: The Wrecking Crew | C463: [28, 35, 80, 9648] | D463: 2026 | E463: en | F463: 30.4309 | G463: 7.037 | H463: 1102 | I463: Crime | J463: Movie | K463: Movie
A464: 1168190 | B464: The Wrecking Crew | C464: [28, 35, 80, 9648] | D464: 2026 | E464: en | F464: 30.4309 | G464: 7.037 | H464: 1102 | I464: Mystery | J464: Movie | K464: Movie
A465: 1022789 | B465: Inside Out 2 | C465: [16, 12, 35, 10751] | D465: 2024 | E465: en | F465: 30.3662 | G465: 7.542 | H465: 6746 | I465: Animation | J465: Movie | K465: Movie
A466: 1022789 | B466: Inside Out 2 | C466: [16, 12, 35, 10751] | D466: 2024 | E466: en | F466: 30.3662 | G466: 7.542 | H466: 6746 | I466: Adventure | J466: Movie | K466: Movie
A467: 1022789 | B467: Inside Out 2 | C467: [16, 12, 35, 10751] | D467: 2024 | E467: en | F467: 30.3662 | G467: 7.542 | H467: 6746 | I467: Comedy | J467: Movie | K467: Movie
A468: 1022789 | B468: Inside Out 2 | C468: [16, 12, 35, 10751] | D468: 2024 | E468: en | F468: 30.3662 | G468: 7.542 | H468: 6746 | I468: Family | J468: Movie | K468: Movie
A469: 1272837 | B469: 28 Years Later: The Bone Temple | C469: [27, 53, 878] | D469: 2026 | E469: en | F469: 30.3279 | G469: 7.12 | H469: 1344 | I469: Horror | J469: Movie | K469: Movie
A470: 1272837 | B470: 28 Years Later: The Bone Temple | C470: [27, 53, 878] | D470: 2026 | E470: en | F470: 30.3279 | G470: 7.12 | H470: 1344 | I470: Thriller | J470: Movie | K470: Movie
A471: 1272837 | B471: 28 Years Later: The Bone Temple | C471: [27, 53, 878] | D471: 2026 | E471: en | F471: 30.3279 | G471: 7.12 | H471: 1344 | I471: Science Fiction | J471: Movie | K471: Movie
A472: 14836 | B472: Coraline | C472: [16, 10751, 14] | D472: 2009 | E472: en | F472: 30.2852 | G472: 7.916 | H472: 9075 | I472: Animation | J472: Movie | K472: Movie
... A1082: 608812 | B1082: Handjob Cabin | C1082: [27, 35] | D1082: 2015 | E1082: en | F1082: 18.6664 | G1082: 7.1 | H1082: 12 | I1082: Comedy | J1082: Movie | K1082: Movie
A1083: 934750 | B1083: Molester Diary: A Man Who Kept Stroking Ass 2 | C1083: [] | D1083: 1995 | E1083: ja | F1083: 18.6532 | G1083: 6 | H1083: 1 | J1083: Movie | K1083: Movie
A1084: 980571 | B1084: Fractured Justice | C1084: [80, 53] | D1084: 2028 | E1084: en | F1084: 18.555 | G1084: 0 | H1084: 0 | I1084: Crime | J1084: Movie | K1084: Movie
A1085: 980571 | B1085: Fractured Justice | C1085: [80, 53] | D1085: 2028 | E1085: en | F1085: 18.555 | G1085: 0 | H1085: 0 | I1085: Thriller | J1085: Movie | K1085: Movie
A1086: 1231940 | B1086: Nice Sister-in-law 6 | C1086: [10749] | D1086: 2023 | E1086: ko | F1086: 18.5462 | G1086: 4 | H1086: 1 | I1086: Romance | J1086: Movie | K1086: Movie
A1087: 278154 | B1087: Ice Age: Collision Course | C1087: [12, 16, 10751, 35, 878] | D1087: 2016 | E1087: en | F1087: 18.5067 | G1087: 6.116 | H1087: 4893 | I1087: Adventure | J1087: Movie | K1087: Movie
A1088: 278154 | B1088: Ice Age: Collision Course | C1088: [12, 16, 10751, 35, 878] | D1088: 2016 | E1088: en | F1088: 18.5067 | G1088: 6.116 | H1088: 4893 | I1088: Animation | J1088: Movie | K1088: Movie
A1089: 278154 | B1089: Ice Age: Collision Course | C1089: [12, 16, 10751, 35, 878] | D1089: 2016 | E1089: en | F1089: 18.5067 | G1089: 6.116 | H1089: 4893 | I1089: Family | J1089: Movie | K1089: Movie
A1090: 278154 | B1090: Ice Age: Collision Course | C1090: [12, 16, 10751, 35, 878] | D1090: 2016 | E1090: en | F1090: 18.5067 | G1090: 6.116 | H1090: 4893 | I1090: Comedy | J1090: Movie | K1090: Movie
A1091: 278154 | B1091: Ice Age: Collision Course | C1091: [12, 16, 10751, 35, 878] | D1091: 2016 | E1091: en | F1091: 18.5067 | G1091: 6.116 | H1091: 4893 | I1091: Science Fiction | J1091: Movie | K1091: Movie
A1092: 122917 | B1092: The Hobbit: The Battle of the Five Armies | C1092: [28, 12, 14] | D1092: 2014 | E1092: en | F1092: 18.5029 | G1092: 7.336 | H1092: 15434 | I1092: Action | J1092: Movie | K1092: Movie
A1093: 122917 | B1093: The Hobbit: The Battle of the Five Armies | C1093: [28, 12, 14] | D1093: 2014 | E1093: en | F1093: 18.5029 | G1093: 7.336 | H1093: 15434 | I1093: Adventure | J1093: Movie | K1093: Movie
A1094: 122917 | B1094: The Hobbit: The Battle of the Five Armies | C1094: [28, 12, 14] | D1094: 2014 | E1094: en | F1094: 18.5029 | G1094: 7.336 | H1094: 15434 | I1094: Fantasy | J1094: Movie | K1094: Movie
...

Sheet TV Shows
A1: id | B1: name | C1: genre_ids | D1: first_air_date | E1: original_language | F1: popularity | G1: vote_average | H1: vote_count | I1: genres | J1: content_type | K1: content_type2
A2: 124364 | B2: FROM | C2: [9648, 18, 10765] | D2: 2022 | E2: en | F2: 872.1045 | G2: 8.509 | H2: 3852 | I2: Mystery | J2: TV Show | K2: TV Show
A3: 124364 | B3: FROM | C3: [9648, 18, 10765] | D3: 2022 | E3: en | F3: 872.1045 | G3: 8.509 | H3: 3852 | I3: Drama | J3: TV Show | K3: TV Show
A4: 124364 | B4: FROM | C4: [9648, 18, 10765] | D4: 2022 | E4: en | F4: 872.1045 | G4: 8.509 | H4: 3852 | I4: Sci-Fi & Fantasy | J4: TV Show | K4: TV Show
A5: 94997 | B5: House of the Dragon | C5: [10765, 18, 10759] | D5: 2022 | E5: en | F5: 592.0857 | G5: 8.352 | H5: 6391 | I5: Sci-Fi & Fantasy | J5: TV Show | K5: TV Show
A6: 94997 | B6: House of the Dragon | C6: [10765, 18, 10759] | D6: 2022 | E6: en | F6: 592.0857 | G6: 8.352 | H6: 6391 | I6: Drama | J6: TV Show | K6: TV Show
A7: 94997 | B7: House of the Dragon | C7: [10765, 18, 10759] | D7: 2022 | E7: en | F7: 592.0857 | G7: 8.352 | H7: 6391 | I7: Action & Adventure | J7: TV Show | K7: TV Show
A8: 4304 | B8: Xplay | C8: [] | D8: 2003 | E8: en | F8: 397.7885 | G8: 8 | H8: 3 | J8: TV Show | K8: TV Show
A9: 2734 | B9: Law & Order: Special Victims Unit | C9: [80, 18, 9648] | D9: 1999 | E9: en | F9: 303.802 | G9: 7.949 | H9: 4259 | I9: Crime | J9: TV Show | K9: TV Show
A10: 2734 | B10: Law & Order: Special Victims Unit | C10: [80, 18, 9648] | D10: 1999 | E10: en | F10: 303.802 | G10: 7.949 | H10: 4259 | I10: Drama | J10: TV Show | K10: TV Show
A11: 2734 | B11: Law & Order: Special Victims Unit | C11: [80, 18, 9648] | D11: 1999 | E11: en | F11: 303.802 | G11: 7.949 | H11: 4259 | I11: Mystery | J11: TV Show | K11: TV Show
A12: 273240 | B12: Off Campus | C12: [18] | D12: 2026 | E12: en | F12: 284.1439 | G12: 8.982 | H12: 588 | I12: Drama | J12: TV Show | K12: TV Show
A13: 13805 | B13: A Girl's Guide to 21st Century Sex | C13: [99] | D13: 2006 | E13: en | F13: 272.7378 | G13: 5.2 | H13: 18 | I13: Documentary | J13: TV Show | K13: TV Show
A14: 82452 | B14: Avatar: The Last Airbender | C14: [10759, 10765, 18, 10751] | D14: 2024 | E14: en | F14: 268.102 | G14: 7.813 | H14: 1164 | I14: Action & Adventure | J14: TV Show | K14: TV Show
A15: 82452 | B15: Avatar: The Last Airbender | C15: [10759, 10765, 18, 10751] | D15: 2024 | E15: en | F15: 268.102 | G15: 7.813 | H15: 1164 | I15: Sci-Fi & Fantasy | J15: TV Show | K15: TV Show
A16: 82452 | B16: Avatar: The Last Airbender | C16: [10759, 10765, 18, 10751] | D16: 2024 | E16: en | F16: 268.102 | G16: 7.813 | H16: 1164 | I16: Drama | J16: TV Show | K16: TV Show
A17: 82452 | B17: Avatar: The Last Airbender | C17: [10759, 10765, 18, 10751] | D17: 2024 | E17: en | F17: 268.102 | G17: 7.813 | H17: 1164 | I17: Family | J17: TV Show | K17: TV Show
A18: 241002 | B18: Adam's Sweet Agony | C18: [16] | D18: 2024 | E18: ja | F18: 265.819 | G18: 6.611 | H18: 36 | I18: Animation | J18: TV Show | K18: TV Show
A19: 299167 | B19: Dutton Ranch | C19: [37, 18] | D19: 2026 | E19: en | F19: 251.4897 | G19: 9.28 | H19: 330 | I19: Western | J19: TV Show | K19: TV Show
A20: 299167 | B20: Dutton Ranch | C20: [37, 18] | D20: 2026 | E20: en | F20: 251.4897 | G20: 9.28 | H20: 330 | I20: Drama | J20: TV Show | K20: TV Show
... A83: 764 | B83: Midsomer Murders | C83: [80, 18, 9648] | D83: 1997 | E83: en | F83: 158.3244 | G83: 7.5 | H83: 357 | I83: Mystery | J83: TV Show | K83: TV Show
A84: 322649 | B84: CHILL CLUB 推介 | C84: [] | D84: 2020 | E84: cn | F84: 157.5474 | G84: 0 | H84: 0 | J84: TV Show | K84: TV Show
A85: 278178 | B85: I Will Find You | C85: [18, 9648, 80] | D85: 2026 | E85: en | F85: 157.4947 | G85: 8.314 | H85: 161 | I85: Drama | J85: TV Show | K85: TV Show
A86: 278178 | B86: I Will Find You | C86: [18, 9648, 80] | D86: 2026 | E86: en | F86: 157.4947 | G86: 8.314 | H86: 161 | I86: Mystery | J86: TV Show | K86: TV Show
A87: 278178 | B87: I Will Find You | C87: [18, 9648, 80] | D87: 2026 | E87: en | F87: 157.4947 | G87: 8.314 | H87: 161 | I87: Crime | J87: TV Show | K87: TV Show
A88: 232393 | B88: 6 Lovers | C88: [16, 35, 18] | D88: 2021 | E88: ja | F88: 154.9241 | G88: 8.3 | H88: 3 | I88: Animation | J88: TV Show | K88: TV Show
A89: 232393 | B89: 6 Lovers | C89: [16, 35, 18] | D89: 2021 | E89: ja | F89: 154.9241 | G89: 8.3 | H89: 3 | I89: Comedy | J89: TV Show | K89: TV Show
A90: 232393 | B90: 6 Lovers | C90: [16, 35, 18] | D90: 2021 | E90: ja | F90: 154.9241 | G90: 8.3 | H90: 3 | I90: Drama | J90: TV Show | K90: TV Show
A91: 1911 | B91: Bones | C91: [80, 18] | D91: 2005 | E91: en | F91: 150.3328 | G91: 8.186 | H91: 3514 | I91: Crime | J91: TV Show | K91: TV Show
A92: 1911 | B92: Bones | C92: [80, 18] | D92: 2005 | E92: en | F92: 150.3328 | G92: 8.186 | H92: 3514 | I92: Drama | J92: TV Show | K92: TV Show
A93: 1408 | B93: House | C93: [18] | D93: 2004 | E93: en | F93: 149.8852 | G93: 8.566 | H93: 7653 | I93: Drama | J93: TV Show | K93: TV Show
A94: 1431 | B94: CSI: Crime Scene Investigation | C94: [80, 18, 9648] | D94: 2000 | E94: en | F94: 149.2834 | G94: 7.6 | H94: 1393 | I94: Crime | J94: TV Show | K94: TV Show
A95: 1431 | B95: CSI: Crime Scene Investigation | C95: [80, 18, 9648] | D95: 2000 | E95: en | F95: 149.2834 | G95: 7.6 | H95: 1393 | I95: Drama | J95: TV Show | K95: TV Show
A96: 1431 | B96: CSI: Crime Scene Investigation | C96: [80, 18, 9648] | D96: 2000 | E96: en | F96: 149.2834 | G96: 7.6 | H96: 1393 | I96: Mystery | J96: TV Show | K96: TV Show
... A587: 87917 | B587: For All Mankind | C587: [18, 10765, 10768] | D587: 2019 | E587: en | F587: 62.4086 | G587: 7.748 | H587: 959 | I587: War & Politics | J587: TV Show | K587: TV Show
A588: 93643 | B588: TMI SHOW | C588: [] | D588: 2019 | E588: ko | F588: 62.3099 | G588: 0 | H588: 0 | J588: TV Show | K588: TV Show
A589: 74428 | B589: Rosario Tijeras (Mexico) | C589: [18, 80] | D589: 2016 | E589: es | F589: 62.2978 | G589: 7.796 | H589: 2009 | I589: Drama | J589: TV Show | K589: TV Show
A590: 74428 | B590: Rosario Tijeras (Mexico) | C590: [18, 80] | D590: 2016 | E590: es | F590: 62.2978 | G590: 7.796 | H590: 2009 | I590: Crime | J590: TV Show | K590: TV Show
A591: 3452 | B591: Frasier | C591: [35, 10751] | D591: 1993 | E591: en | F591: 62.2804 | G591: 7.7 | H591: 889 | I591: Comedy | J591: TV Show | K591: TV Show
A592: 3452 | B592: Frasier | C592: [35, 10751] | D592: 1993 | E592: en | F592: 62.2804 | G592: 7.7 | H592: 889 | I592: Family | J592: TV Show | K592: TV Show
...

Sheet Genre Lookup
A1: genre_id | B1: genre_name
A2: 28 | B2: Action
A3: 12 | B3: Adventure
A4: 16 | B4: Animation
A5: 35 | B5: Comedy
A6: 80 | B6: Crime
A7: 99 | B7: Documentary
A8: 18 | B8: Drama
A9: 10751 | B9: Family
A10: 14 | B10: Fantasy
A11: 36 | B11: History
A12: 27 | B12: Horror
A13: 10402 | B13: Music
... A28: 10768 | B28: War & Politics

Sheet Analysis
A1: Row Labels | B1: Avg popularity
A2: Music | B2: 17.892927
A3: Horror | B3: 17.515186
A4: Science Fiction | B4: 17.319258
A5: Adventure | B5: 17.262762
A6: Animation | B6: 16.792334
A7: Mystery | B7: 16.738171
A8: Crime | B8: 16.390328
A9: Family | B9: 16.292502
A10: Comedy | B10: 16.241757
A11: Action | B11: 15.736196
A12: Thriller | B12: 15.56119
A13: Fantasy | B13: 14.787634
... A20: Grand Total | B20: 15.649439
A22: Row Labels | B22: Avg Vote Score
A23: Western | B23: 6.91525
A24: War | B24: 6.8866164
A25: History | B25: 6.7772708
A26: Music | B26: 6.7212333
A27: Animation | B27: 6.7191935
A28: Adventure | B28: 6.6174399
A29: Fantasy | B29: 6.5816904
A30: Science Fiction | B30: 6.5513539
A31: Action | B31: 6.5437281
A32: Family | B32: 6.5309556
A33: Crime | B33: 6.5208382
A34: Drama | B34: 6.4999482
... A42: Grand Total | B42: 6.4910984
A45: Row Labels | B45: Unique Titles
A46: 1878 | B46: 2
A47: 1892 | B47: 1
A48: 1893 | B48: 2
A49: 1895 | B49: 5
A50: 1896 | B50: 4
A51: 1897 | B51: 2
A52: 1898 | B52: 1
A53: 1899 | B53: 2
A54: 1900 | B54: 2
A55: 1901 | B55: 1
A56: 1906 | B56: 1
...
